Workbook

Sheet Cover
A1: AETHERIS AI S.r.l. · Financial Model v3.0 (Grounded & Proven)
A2: Financial Model v3.0 — Conservative
A3: One-man show + advisors → team · Founder bootstrap → Smart&Start + pre-seed
B5: Sheets
B6: Cover | C6: Questa pagina
B7: Assumptions | C7: Tutti gli input editabili (in blu, sfondo giallo)
B8: Revenue | C8: Revenue build bottom-up conservative
B9: PL_Monthly | C9: Conto economico mensile 36 mesi
B10: PL_Annual | C10: Sintesi annuale da monthly
B11: CashFlow | C11: Cash flow + scenari base/pessimistico/ottimistico
B12: Team | C12: Team evolution + salary
B13: Capex | C13: Capex + ammortamenti
B14: KPIs | C14: Dashboard KPI operativi
B15: Smart&Start | C15: Application form precompilato
B18: V3.0 — Key changes vs V2.0
B19: • Customer numbers conservativi: Y1 1-2, Y2 3-5, Y3 8-12 (vs 3-5/10-15/25-30)
B20: • ACV Y1 ridotto a €30-50k (vs €45k) — primi clienti pagano meno
B21: • Team evolution realistica: founder solo per 6 mesi, poi advisor+part-time
B22: • Funding Phase 1: €200-300k (vs €300-400k) — proporzionato al team
B23: • Persona costs: founder stipendio €30k Y1 (no salary equity-only iniziale)
B24: • Cloud costs ridotti: M0-M3 zero (self-hosted), poi scaling graduale
B25: • Aggiunto foglio Team con salary espliciti per ruolo

Sheet Assumptions
A1: AETHERIS AI S.r.l. · Financial Model v3.0 (Grounded & Proven)
A2: Assumptions v3.0 — Conservative
A3: Tutti i valori editabili sono in BLU. Modifica per scenari.
B5: # | C5: Parametro | D5: Valore | E5: Unit | F5: Trigger | G5: Note
C6: ─── REVENUE ───
B7: R1 | C7: Y1 — Clienti (1 design partner + 1 paid pilot) | D7: 2 | E7: clienti | F7: Gate 2 | G7: Realistico per founder solo
B8: R2 | C8: Y2 — Clienti paganti (1 design + 4 paid) | D8: 5 | E8: clienti | F8: Gate 3-4 | G8: Include 1 design partner rinnovato
B9: R3 | C9: Y3 — Clienti paganti (rinnovati + nuovi) | D9: 10 | E9: clienti | F9: Gate 5 | G9: Mix design rinnovati + new acquisition
B10: R4 | C10: Y1 — ACV medio | D10: 40 | E10: k€ | F10: Mix design+pilot | G10: Range 30-50k
B11: R5 | C11: Y2 — ACV medio | D11: 80 | E11: k€ | F11: Upselling | G11: Range 60-90k
B12: R6 | C12: Y3 — ACV medio | D12: 115 | E12: k€ | F12: Bundling | G12: Range 100-140k
B13: R7 | C13: Y1 % Subscription | D13: 30 | E13: % | F13: Design+PoC | G13: 70% services
B14: R8 | C14: Y2 % Subscription | D14: 50 | E14: % | F14: Mix | G14: 30% services, 20% managed
B15: R9 | C15: Y3 % Subscription | D15: 60 | E15: % | F15: Mix | G15: 20% services, 20% managed+usage
C16: ─── CLOUD ───
B17: C1 | C17: Cloud / GPU M0-M3 (self-hosted only) | D17: 0 | E17: k€/mese | F17: PoC phase | G17: Ollama, Qdrant self-hosted, free tiers
B18: C2 | C18: Cloud / GPU Y2 medio | D18: 4 | E18: k€/mese | F18: Primi clienti | G18: Inference + serving
B19: C3 | C19: Cloud / GPU Y3 medio | D19: 9 | E19: k€/mese | F19: Più carichi | G19: Ottimizzato
C20: ─── TEAM ───
B21: T1 | C21: Founder stipendio M0-M3 (equity-only) | D21: 0 | E21: k€/anno | F21: Bootstrap | G21: Solo equity
B22: T2 | C22: Founder stipendio M3-M12 (stipendio minimo) | D22: 30 | E22: k€/anno | F22: Da M3 | G22: € 2.5k/mese lordi
B23: T3 | C23: Founder stipendio Y2 (full salary) | D23: 50 | E23: k€/anno | F23: Da M13 | G23: € 4.2k/mese
B24: T4 | C24: Founder stipendio Y3 (market rate) | D24: 70 | E24: k€/anno | F24: Da M25 | G24: € 5.8k/mese
B25: T5 | C25: Part-time AI engineer M6-M12 (collaboration) | D25: 18 | E25: k€/anno | F25: Da M6 | G25: 20-40% FTE
B26: T6 | C26: Co-founder commercial M9+ (full) | D26: 60 | E26: k€/anno | F26: Da M9 | G26: + equity 5-10%
B27: T7 | C27: Senior AI engineer Y2 (full) | D27: 55 | E27: k€/anno | F27: Da M13 | G27: Market rate
B28: T8 | C28: Senior AI engineer Y3 (full) | D28: 60 | E28: k€/anno | F28: Da M25 | G28: +1 hire
B29: T9 | C29: Customer success Y2 (part-time) | D29: 18 | E29: k€/anno | F29: Da M13 | G29: 50% FTE
B30: T10 | C30: Customer success Y3 (full) | D30: 45 | E30: k€/anno | F30: Da M25 | G30: Full hire
C31: ─── OPEX ───
B32: O1 | C32: Opex M0-M3 (bootstrap) | D32: 1 | E32: k€/mese | F32: Lean phase | G32: Solo tool essenziali + dominio
B33: O2 | C33: Opex M4-M12 | D33: 3 | E33: k€/mese | F33: Post-PoC | G33: Marketing base, legal, contabilità
B34: O3 | C34: Opex Y2 medio | D34: 6 | E34: k€/mese | F34: Scale-up | G34: Fiere, marketing, sales ops
B35: O4 | C35: Opex Y3 medio | D35: 10 | E35: k€/mese | F35: EU expansion | G35: Branding, content, fiere EU
C36: ─── R&D ───
B37: R1a | C37: R&D M0-M6 (PoC + evaluation) | D37: 0 | E37: k€/mese | F37: Bootstrap | G37: Founder time = R&D
B38: R1b | C38: R&D M6-M12 | D38: 1 | E38: k€/mese | F38: Post-PoC | G38: Tool, dataset, eval
B39: R1c | C39: R&D Y2 medio | D39: 3 | E39: k€/mese | F39: Modelli custom | G39: Vertical AI, eval suite
B40: R1d | C40: R&D Y3 medio | D40: 5 | E40: k€/mese | F40: Federated, edge | G40: Roadmap items
C41: ─── TAXES / INFLATION ───
...

Sheet Revenue
A1: AETHERIS AI S.r.l. · Financial Model v3.0 (Grounded & Proven)
A2: Revenue Build v3.0 — Conservative
A3: Bottom-up: 2 clienti Y1 → 5 Y2 → 10 Y3
C5: Voce | D5: Y1 | E5: Y2 | F5: Y3 | G5: Unit | H5: Note
B6: Numero clienti paganti | D6: =Assumptions!D7 | E6: =Assumptions!D8 | F6: =Assumptions!D9 | G6: R1-R3
B7: ACV medio | D7: =Assumptions!D10 | E7: =Assumptions!D11 | F7: =Assumptions!D12 | G7: R4-R6
B8: Ricavi totali (k€) | D8: =D6*D7 | E8: =E6*E7 | F8: =F6*F7 | G8: N × ACV
B9: di cui Subscription | D9: =D8*Assumptions!D13 | E9: =E8*Assumptions!D14 | F9: =F8*Assumptions!D15 | G9: R7-R9
B10: di cui Servizi | D10: =D8-D9 | E10: =E8-E9 | F10: =F8-F9 | G10: Residuo
B12: Memoria: revenue range | D12: € 80k | E12: € 400k | F12: € 1.150k | G12: Punto medio
B13: Range conservative Y1/Y2/Y3 | D13: € 50-100k | E13: € 300-500k | F13: € 800k-1.5M | G13: Range 80% confidenza
B16: Nota: Y1 con founder solo = realisticamente 1-2 clienti, NON 3-5 come in v2.0.
B17: Anche con ACV conservativo €40k, si tratta di € 80k totali, gestibile da solo.
B18: La crescita a Y2 (5 clienti) richiede già un co-founder commerciale per essere raggiungibile.

Sheet PL_Monthly
A1: AETHERIS AI S.r.l. · Financial Model v3.0 (Grounded & Proven)
A2: Conto Economico Mensile v3.0 — 36 mesi
A3: Founder solo M0-M6, poi team evolution graduale
B5: Voce (k€) | C5: M1 | D5: M2 | E5: M3 | F5: M4 | G5: M5 | H5: M6 | I5: M7 | J5: M8 | K5: M9 | L5: M10 | M5: M11 | N5: M12 | O5: M13 | P5: M14 | Q5: M15 | R5: M16 | S5: M17 | T5: M18 | U5: M19 | V5: M20 | W5: M21 | X5: M22 | Y5: M23 | Z5: M24 | AA5: M25 | AB5: M26 | AC5: M27 | AD5: M28 | AE5: M29 | AF5: M30 | AG5: M31 | AH5: M32 | AI5: M33 | AJ5: M34 | AK5: M35 | AL5: M36 | AM5: TOTAL Y1 | AN5: TOTAL Y2 | AO5: TOTAL Y3
B6: Ricavi totali | C6: =Revenue!$D$8*0.0833 | D6: =Revenue!$D$8*0.1667 | E6: =Revenue!$D$8*0.2500 | F6: =Revenue!$D$8*0.3333 | G6: =Revenue!$D$8*0.4167 | H6: =Revenue!$D$8*0.5000 | I6: =Revenue!$D$8*0.5833 | J6: =Revenue!$D$8*0.6667 | K6: =Revenue!$D$8*0.7500 | L6: =Revenue!$D$8*0.8333 | M6: =Revenue!$D$8*0.9167 | N6: =Revenue!$D$8*1.0000 | O6: =Revenue!$E$8*0.0840 | P6: =Revenue!$E$8*0.0847 | Q6: =Revenue!$E$8*0.0854 | R6: =Revenue!$E$8*0.0861 | S6: =Revenue!$E$8*0.0868 | T6: =Revenue!$E$8*0.0875 | U6: =Revenue!$E$8*0.0882 | V6: =Revenue!$E$8*0.0889 | W6: =Revenue!$E$8*0.0896 | X6: =Revenue!$E$8*0.0903 | Y6: =Revenue!$E$8*0.0910 | Z6: =Revenue!$E$8*0.0917 | AA6: =Revenue!$F$8*0.0931 | AB6: =Revenue!$F$8*0.0944 | AC6: =Revenue!$F$8*0.0958 | AD6: =Revenue!$F$8*0.0972 | AE6: =Revenue!$F$8*0.0986 | AF6: =Revenue!$F$8*0.1000 | AG6: =Revenue!$F$8*0.1014 | AH6: =Revenue!$F$8*0.1028 | AI6: =Revenue!$F$8*0.1042 | AJ6: =Revenue!$F$8*0.1056 | AK6: =Revenue!$F$8*0.1069 | AL6: =Revenue!$F$8*0.1083 | AM6: =SUM(C6:N6) | AN6: =SUM(O6:Z6) | AO6: =SUM(AA6:AL6)
B7: COGS (cloud + GPU) | C7: 0 | D7: 0 | E7: 0 | F7: =(1/9.0) * 1 | G7: =(2/9.0) * 1 | H7: =(3/9.0) * 1 | I7: =(4/9.0) * 1 | J7: =(5/9.0) * 1 | K7: =(6/9.0) * 1 | L7: =(7/9.0) * 1 | M7: =(8/9.0) * 1 | N7: =(9/9.0) * 1 | O7: 4 | P7: 4 | Q7: 4 | R7: 4 | S7: 4 | T7: 4 | U7: 4 | V7: 4 | W7: 4 | X7: 4 | Y7: 4 | Z7: 4 | AA7: 9 | AB7: 9 | AC7: 9 | AD7: 9 | AE7: 9 | AF7: 9 | AG7: 9 | AH7: 9 | AI7: 9 | AJ7: 9 | AK7: 9 | AL7: 9 | AM7: =SUM(C7:N7) | AN7: =SUM(O7:Z7) | AO7: =SUM(AA7:AL7)
B8: Margine Lordo | C8: =C6-C7 | D8: =D6-D7 | E8: =E6-E7 | F8: =F6-F7 | G8: =G6-G7 | H8: =H6-H7 | I8: =I6-I7 | J8: =J6-J7 | ... AL8: =AL6-AL7 | AM8: =SUM(C8:N8) | AN8: =SUM(O8:Z8) | AO8: =SUM(AA8:AL8)
B9: Costi personale | C9: 0 | D9: 0 | E9: 0 | F9: 2.5 | G9: 2.5 | H9: 2.5 | I9: 4 | J9: 4 | K9: 4 | L9: 4 | M9: 4 | N9: 4 | O9: 15.3 | P9: 15.3 | Q9: 15.3 | R9: 15.3 | S9: 15.3 | T9: 15.3 | U9: 15.3 | V9: 15.3 | W9: 15.3 | X9: 15.3 | Y9: 15.3 | Z9: 15.3 | AA9: 19.6 | AB9: 19.6 | AC9: 19.6 | AD9: 19.6 | AE9: 19.6 | AF9: 19.6 | AG9: 19.6 | AH9: 19.6 | AI9: 19.6 | AJ9: 19.6 | AK9: 19.6 | AL9: 19.6 | AM9: =SUM(C9:N9) | AN9: =SUM(O9:Z9) | AO9: =SUM(AA9:AL9)
B10: Costi operativi | C10: 1 | D10: 1 | E10: 1 | F10: 3 | G10: 3 | H10: 3 | I10: 3 | J10: 3 | K10: 3 | L10: 3 | M10: 3 | N10: 3 | O10: 6 | P10: 6 | Q10: 6 | R10: 6 | S10: 6 | T10: 6 | U10: 6 | V10: 6 | W10: 6 | X10: 6 | Y10: 6 | Z10: 6 | AA10: 10 | AB10: 10 | AC10: 10 | AD10: 10 | AE10: 10 | AF10: 10 | AG10: 10 | AH10: 10 | AI10: 10 | AJ10: 10 | AK10: 10 | AL10: 10 | AM10: =SUM(C10:N10) | AN10: =SUM(O10:Z10) | AO10: =SUM(AA10:AL10)
B11: R&D e innovazione | C11: 0 | D11: 0 | E11: 0 | F11: 0 | G11: 0 | H11: 0 | I11: 1 | J11: 1 | K11: 1 | L11: 1 | M11: 1 | N11: 1 | O11: 3 | P11: 3 | Q11: 3 | R11: 3 | S11: 3 | T11: 3 | U11: 3 | V11: 3 | W11: 3 | X11: 3 | Y11: 3 | Z11: 3 | AA11: 5 | AB11: 5 | AC11: 5 | AD11: 5 | AE11: 5 | AF11: 5 | AG11: 5 | AH11: 5 | AI11: 5 | AJ11: 5 | AK11: 5 | AL11: 5 | AM11: =SUM(C11:N11) | AN11: =SUM(O11:Z11) | AO11: =SUM(AA11:AL11)
B12: EBITDA | C12: =C8-C9-C10-C11 | D12: =D8-D9-D10-D11 | E12: =E8-E9-E10-E11 | F12: =F8-F9-F10-F11 | G12: =G8-G9-G10-G11 | H12: =H8-H9-H10-H11 | I12: =I8-I9-I10-I11 | J12: =J8-J9-J10-J11 | ... AL12: =AL8-AL9-AL10-AL11 | AM12: =SUM(C12:N12) | AN12: =SUM(O12:Z12) | AO12: =SUM(AA12:AL12)
B14: Capex | C14: 3 | D14: 0 | E14: 0 | F14: 0 | G14: 0 | H14: 0.5 | I14: 0 | J14: 0 | K14: 0 | L14: 0 | M14: 0 | N14: 0 | O14: 3 | P14: 0 | Q14: 0 | R14: 0 | S14: 0 | T14: 0 | U14: 0 | V14: 0 | W14: 0 | X14: 0 | Y14: 0 | Z14: 0 | AA14: 5 | AB14: 0 | AC14: 0 | AD14: 0 | AE14: 0 | AF14: 0 | AG14: 0 | AH14: 0 | AI14: 0 | AJ14: 0 | AK14: 0 | AL14: 0 | AM14: =SUM(C14:N14) | AN14: =SUM(O14:Z14) | AO14: =SUM(AA14:AL14)
B15: Smart&Start (inflow) | C15: 0 | D15: 200 | E15: 0 | F15: 0 | G15: 0 | H15: 0 | I15: 0 | J15: 0 | K15: 0 | L15: 0 | M15: 0 | N15: 0 | O15: 0 | P15: 0 | Q15: 0 | R15: 0 | S15: 0 | T15: 0 | U15: 0 | V15: 0 | W15: 0 | X15: 0 | Y15: 0 | Z15: 0 | AA15: 0 | AB15: 0 | AC15: 0 | AD15: 0 | AE15: 0 | AF15: 0 | AG15: 0 | AH15: 0 | AI15: 0 | AJ15: 0 | AK15: 0 | AL15: 0 | AM15: =SUM(C15:N15) | AN15: =SUM(O15:Z15) | AO15: =SUM(AA15:AL15)
B16: Acceleratori (inflow) | C16: 0 | D16: 0 | E16: 0 | F16: 30 | G16: 0 | H16: 0 | I16: 0 | J16: 0 | K16: 0 | L16: 0 | M16: 0 | N16: 0 | O16: 0 | P16: 0 | Q16: 0 | R16: 0 | S16: 0 | T16: 0 | U16: 0 | V16: 0 | W16: 0 | X16: 0 | Y16: 0 | Z16: 0 | AA16: 0 | AB16: 0 | AC16: 0 | AD16: 0 | AE16: 0 | AF16: 0 | AG16: 0 | AH16: 0 | AI16: 0 | AJ16: 0 | AK16: 0 | AL16: 0 | AM16: =SUM(C16:N16) | AN16: =SUM(O16:Z16) | AO16: =SUM(AA16:AL16)
B17: Round pre-seed (inflow) | C17: 0 | D17: 0 | E17: 0 | F17: 0 | G17: 0 | H17: 0 | I17: 0 | J17: 100 | K17: 0 | L17: 0 | M17: 0 | N17: 0 | O17: 0 | P17: 0 | Q17: 0 | R17: 0 | S17: 0 | T17: 0 | U17: 0 | V17: 0 | W17: 0 | X17: 0 | Y17: 0 | Z17: 0 | AA17: 0 | AB17: 0 | AC17: 0 | AD17: 0 | AE17: 0 | AF17: 0 | AG17: 0 | AH17: 0 | AI17: 0 | AJ17: 0 | AK17: 0 | AL17: 0 | AM17: =SUM(C17:N17) | AN17: =SUM(O17:Z17) | AO17: =SUM(AA17:AL17)
B18: Round seed (inflow) | C18: 0 | D18: 0 | E18: 0 | F18: 0 | G18: 0 | H18: 0 | I18: 0 | J18: 0 | K18: 0 | L18: 0 | M18: 0 | N18: 0 | O18: 0 | P18: 0 | Q18: 0 | R18: 0 | S18: 0 | T18: 750 | U18: 0 | V18: 0 | W18: 0 | X18: 0 | Y18: 0 | Z18: 0 | AA18: 0 | AB18: 0 | AC18: 0 | AD18: 0 | AE18: 0 | AF18: 0 | AG18: 0 | AH18: 0 | AI18: 0 | AJ18: 0 | AK18: 0 | AL18: 0 | AM18: =SUM(C18:N18) | AN18: =SUM(O18:Z18) | AO18: =SUM(AA18:AL18)
B20: Net cash flow | C20: =C12-C14+C15+C16+C17+C18 | D20: =D12-D14+D15+D16+D17+D18 | E20: =E12-E14+E15+E16+E17+E18 | F20: =F12-F14+F15+F16+F17+F18 | G20: =G12-G14+G15+G16+G17+G18 | H20: =H12-H14+H15+H16+H17+H18 | I20: =I12-I14+I15+I16+I17+I18 | J20: =J12-J14+J15+J16+J17+J18 | ... AL20: =AL12-AL14+AL15+AL16+AL17+AL18 | AM20: =SUM(C20:N20) | AN20: =SUM(O20:Z20) | AO20: =SUM(AA20:AL20)
B21: Cash position (cumulativa) | C21: =C20 | D21: =C21+D20 | E21: =D21+E20 | F21: =E21+F20 | G21: =F21+G20 | H21: =G21+H20 | I21: =H21+I20 | J21: =I21+J20 | K21: =J21+K20 | ... AL21: =AK21+AL20 | AM21: =M21 | AN21: =Y21 | AO21: =AK21
B23: Runway (mesi) | C23: =IF(C21<=0,"BREAK",IF(C20>=0,"INF",-(C21)/C20)) | D23: =IF(D21<=0,"BREAK",IF(D20>=0,"INF",-(D21)/D20)) | E23: =IF(E21<=0,"BREAK",IF(E20>=0,"INF",-(E21)/E20)) | F23: =IF(F21<=0,"BREAK",IF(F20>=0,"INF",-(F21)/F20)) | G23: =IF(G21<=0,"BREAK",IF(G20>=0,"INF",-(G21)/G20)) | H23: =IF(H21<=0,"BREAK",IF(H20>=0,"INF",-(H21)/H20)) | I23: =IF(I21<=0,"BREAK",IF(I20>=0,"INF",-(I21)/I20)) | J23: =IF(J21<=0,"BREAK",IF(J20>=0,"INF",-(J21)/J20)) | ... AL23: =IF(AL21<=0,"BREAK",IF(AL20>=0,"INF",-(AL21)/AL20))

Sheet PL_Annual
A1: AETHERIS AI S.r.l. · Financial Model v3.0 (Grounded & Proven)
A2: Conto Economico Annuale v3.0
A3: Sintesi da PL_Monthly · conservativa, realistica
C5: Voce (k€) | D5: Anno 1 | E5: Anno 2 | F5: Anno 3 | G5: 3Y Total
B6: Ricavi totali | D6: =PL_Monthly!AM6 | E6: =PL_Monthly!AN6 | F6: =PL_Monthly!AO6 | G6: =SUM(D6:F6)
B7: COGS | D7: =PL_Monthly!AM7 | E7: =PL_Monthly!AN7 | F7: =PL_Monthly!AO7 | G7: =SUM(D7:F7)
B8: Margine Lordo | D8: =PL_Monthly!AM8 | E8: =PL_Monthly!AN8 | F8: =PL_Monthly!AO8 | G8: =SUM(D8:F8)
B9: Personale | D9: =PL_Monthly!AM9 | E9: =PL_Monthly!AN9 | F9: =PL_Monthly!AO9 | G9: =SUM(D9:F9)
B10: Costi operativi | D10: =PL_Monthly!AM10 | E10: =PL_Monthly!AN10 | F10: =PL_Monthly!AO10 | G10: =SUM(D10:F10)
B11: R&D | D11: =PL_Monthly!AM11 | E11: =PL_Monthly!AN11 | F11: =PL_Monthly!AO11 | G11: =SUM(D11:F11)
B12: EBITDA | D12: =PL_Monthly!AM12 | E12: =PL_Monthly!AN12 | F12: =PL_Monthly!AO12 | G12: =SUM(D12:F12)
B13: Net cash flow | D13: =PL_Monthly!AM20 | E13: =PL_Monthly!AN20 | F13: =PL_Monthly!AO20 | G13: =SUM(D13:F13)
B15: Margine % | D15: =D8/D6 | E15: =E8/E6 | F15: =F8/F6

Sheet CashFlow
A1: AETHERIS AI S.r.l. · Financial Model v3.0 (Grounded & Proven)
A2: Cash Flow + Scenari v3.0
A3: Base / Pessimistico / Ottimistico
C5: Voce (k€) | D5: Anno 1 | E5: Anno 2 | F5: Anno 3
B6: Operating cash flow | D6: ==PL_Monthly!AM20 | E6: ==PL_Monthly!AN20 | F6: ==PL_Monthly!AO20
B7: Investing cash flow (capex) | D7: ==-SUM(PL_Monthly!C14:AL14) | E7: ==-SUM(PL_Monthly!C14:AL14) | F7: ==-SUM(PL_Monthly!C14:AL14)
B8: Financing cash flow | D8: ==PL_Monthly!AM15+PL_Monthly!AM16+PL_Monthly!AM17+PL_Monthly!AM18 | E8: ==PL_Monthly!AN15+PL_Monthly!AN16+PL_Monthly!AN17+PL_Monthly!AN18 | F8: ==PL_Monthly!AO15+PL_Monthly!AO16+PL_Monthly!AO17+PL_Monthly!AO18
B9: Net change in cash | D9: =SUM(D6:D8) | E9: =SUM(D6:D8) | F9: =SUM(D6:D8)
B10: Cash position end of year | D10: =PL_Monthly!M21 | E10: =PL_Monthly!Y21 | F10: =PL_Monthly!AK21
B13: Scenari (modifica per simulare)
B14: Revenue Y3 (Base) | C14: =PL_Annual!F6
B15: Revenue Y3 (Pessimistico -30%) | C15: =PL_Annual!F6*0.7
B16: Revenue Y3 (Ottimistico +30%) | C16: =PL_Annual!F6*1.3
B17: EBITDA Y3 (Base) | C17: =PL_Annual!F12
B18: EBITDA Y3 (Pessimistico) | C18: =PL_Annual!F12*0.5
B19: EBITDA Y3 (Ottimistico) | C19: =PL_Annual!F12*1.5
B20: Team Y3 (Base) | C20: 5
B21: Team Y3 (Pessimistico) | C21: 3
B22: Team Y3 (Ottimistico) | C22: 8
B23: Cash position Y3 (Base) | C23: =PL_Monthly!AK21
B24: Cash position Y3 (Pessimistico) | C24: =PL_Monthly!AK21*0.5
B25: Cash position Y3 (Ottimistico) | C25: =PL_Monthly!AK21*1.5

Sheet Team
A1: AETHERIS AI S.r.l. · Financial Model v3.0 (Grounded & Proven)
A2: Team Evolution v3.0 — Realistic
A3: Founder solo → +advisor → +part-time → +co-founder → team
C5: Ruolo | D5: Y1 FTE | E5: Y2 FTE | F5: Y3 FTE | G5: Salary Y1 (k€) | H5: Salary Y2 (k€) | I5: Salary Y3 (k€)
B6: Founder & CEO/CTO | C6: 0.5 | D6: 1 | E6: 1 | F6: 30 | G6: 50 | H6: 70
B7: Co-founder Commercial | C7: 0 | D7: 0 | E7: 1 | F7: 0 | G7: 0 | H7: 60
B8: Senior AI Engineer | C8: 0.3 | D8: 1 | E8: 1 | F8: 18 | G8: 55 | H8: 60
B9: Customer Success | C9: 0 | D9: 0.5 | E9: 1 | F9: 0 | G9: 18 | H9: 45
B10: Total FTE (avg) | C10: 0.8 | D10: 2.5 | E10: 4 | F10: 48 | G10: 123 | H10: 235
B14: Hiring plan (24 mesi)
B15: M0 | C15: Founder solo + bootstrap
B16: M3 | C16: + advisor AI Act (1-2% equity) + advisor industry (1-2% equity)
B17: M6 | C17: + 1 part-time AI engineer (collaboration)
B18: M9 | C18: + co-founder commerciale (5-10% equity + salary)
B19: M12 | C19: + 1 senior AI engineer (full) + 1 part-time customer success
B20: M18 | C20: + 1 customer success full + 1 marketing/sales
B21: M24 | C21: Team completo ~5 FTE

Sheet Capex
A1: AETHERIS AI S.r.l. · Financial Model v3.0 (Grounded & Proven)
A2: Capex & Ammortamenti v3.0
A3: Conservativo: focus su setup + refresh, no edtech esagerati
C5: Voce | D5: Y1 | E5: Y2 | F5: Y3 | G5: Ammort. (anni)
B6: Laptop / Workstation | C6: 2 | D6: 1 | E6: 1 | F6: 3
B7: GPU used per PoC | C7: 0.5 | D7: 0 | E7: 0 | F7: 3
B8: Jetson Orin (edge demo) | C8: 0.5 | D8: 0 | E8: 0.5 | F8: 3
B9: Marchi e brevetti | C9: 0 | D9: 1 | E9: 1 | F9: 5
B10: Server on-premise (opzionale) | C10: 0 | D10: 0 | E10: 2 | F10: 3
B11: Attrezzature demo (fiere) | C11: 0 | D11: 1 | E11: 0.5 | F11: 3
B12: TOTALE Capex | C12: =SUM(C6:C11) | D12: =SUM(D6:D11) | E12: =SUM(E6:E11)
B14: Ammortamento annuo (k€) | C14: =C12/3 | D14: =D12/3 | E14: =E12/3

Sheet KPIs
A1: AETHERIS AI S.r.l. · Financial Model v3.0 (Grounded & Proven)
A2: KPI Dashboard v3.0
A3: Tutti i KPI calcolati automaticamente
C5: KPI | D5: Y1 | E5: Y2 | F5: Y3 | G5: Target Y3
B6: Clienti paganti | D6: =Revenue!D6 | E6: =Revenue!E6 | F6: =Revenue!F6 | G6: 10
B7: ACV medio (k€) | D7: =Revenue!D7 | E7: =Revenue!E7 | F7: =Revenue!F7 | G7: € 115k
B8: ARR (k€) | D8: =Revenue!D8*Assumptions!D13 | E8: =Revenue!E8*Assumptions!D14 | F8: =Revenue!F8*Assumptions!D15 | G8: € 690k
B9: Gross margin | D9: =PL_Annual!D8/PL_Annual!D6 | E9: =PL_Annual!E8/PL_Annual!E6 | F9: =PL_Annual!F8/PL_Annual!F6 | G9: 70%
B10: EBITDA (k€) | D10: =PL_Annual!D12 | E10: =PL_Annual!E12 | F10: =PL_Annual!F12 | G10: +€ 200k
B11: Cash position end (k€) | D11: =PL_Monthly!M21 | E11: =PL_Monthly!Y21 | F11: =PL_Monthly!AK21 | G11: € 800k+
B12: Burn rate medio mensile (k€) | D12: =-AVERAGE(PL_Monthly!C12:PL_Monthly!N12) | E12: =-AVERAGE(PL_Monthly!O12:PL_Monthly!Z12) | F12: =-AVERAGE(PL_Monthly!AA12:PL_Monthly!AL12) | G12: Cash positive Y3
B13: Runway (mesi) | D13: =IF(M21<=0,"BREAK",IF(C20>=0,"INF",-M21/C20)) | E13: =IF(Y21<=0,"BREAK",IF(O20>=0,"INF",-Y21/O20)) | F13: =IF(AK21<=0,"BREAK",IF(AA20>=0,"INF",-AK21/AA20)) | G13: ∞
B14: Team (FTE medi) | D14: =Team!C6 | E14: =Team!D6 | F14: =Team!E6 | G14: 5
B15: PoC pubblicati (GitHub) | D15: 3 | E15: 3 | F15: 3 | G15: 3
B16: Blog post pubblicati | D16: 3 | E16: 4 | F16: 6 | G16: 6
B17: Advisor firmati | D17: 2 | E17: 4 | F17: 5 | G17: 5+

Sheet Smart&Start
A1: AETHERIS AI S.r.l. · Financial Model v3.0 (Grounded & Proven)
A2: Smart&Start Italia — Pre-application v3.0
A3: Versione conservativa, founder solo + advisor
B5: Sezione 1 — Dati anagrafici
B6: Ragione sociale | C6: Aetheris AI S.r.l.
B7: Forma giuridica | C7: S.r.l. (Startup Innovativa)
B8: Sede legale | C8: Toscana, Italia
B9: Settore (ATECO) | C9: 62.01 — Custom software development
B10: Codice fiscale / P.IVA | C10: [Da compilare post-costituzione]
B11: Team al momento della domanda | C11: 1 founder + 2 advisor (AI Act + industry)
B12: Sezione 2 — Founder
B13: Founder principale | C13: [Nome Cognome, Founder & CEO/CTO]
B14: Anni di esperienza AI/ML | C14: 5+ anni
B15: Track record production | C15: 100k+ users/day, 99.9% uptime, €2M+ impact, 3 PoC pubblicati
B16: Sezione 3 — Progetto
B17: Titolo del piano | C17: Aetheris AI — Applied AI Infrastructure for European Industry
B18: Descrizione sintetica | C18: Piattaforma europea di Applied AI (GenAI + CV + Predictive AI + Agents) per aziende industriali nei verticali Energy e Manufacturing, conforme all'AI Act.
B19: Importo richiesto (k€) | C19: =Assumptions!D30
B20: Spesa totale del piano (k€) | C20: =Assumptions!D30+50
B21: Sezione 4 — Innovatività
B22: Elementi di innovazione tecnologica | C22: Piattaforma multi-pilastro unificata, evaluation infrastructure proprietaria, AI Act-ready by design. 3 PoC pubblicati come prova.
B23: Elementi di innovazione di processo | C23: Customer discovery strutturata, 5-Gate roadmap verificabile, Proof of Capability stack.
B24: Sezione 5 — Mercato e go-to-market
B25: Mercato target | C25: Energy + Manufacturing in EU (Tuscany focus)
B26: Bottom-up revenue Y1 (k€) | C26: =Revenue!D8
B27: Bottom-up revenue Y2 (k€) | C27: =Revenue!E8
B28: Bottom-up revenue Y3 (k€) | C28: =Revenue!F8
B29: Sezione 6 — Impatto occupazionale
B30: Nuovi posti di lavoro creati (3 anni) | C30: =Team!E10-1
B31: Sezione 7 — Use of funds Phase 1
B32: 30% Founder stipend (Y1) | C32: =Assumptions!D30*0.30
B33: 30% Cloud + PoC infrastructure | C33: =Assumptions!D30*0.30
B34: 20% Customer pilot + discovery | C34: =Assumptions!D30*0.20
B35: 10% Legal/AI Act compliance | C35: =Assumptions!D30*0.10
B36: 10% Marketing + outreach | C36: =Assumptions!D30*0.10
